Workbook

Sheet Panduan
A1: Digital Ads Ultimate Skill 2026: Workbook Latihan
A2: Praktik end-to-end Google, Meta, TikTok, LinkedIn, dan marketplace. Semua data FIKTIF (brand contoh Nusa Apparel). Repo: github.com/shafry00/digital-ads-ultimate-skill-2026
A4: CARA PAKAI (5 langkah)
A5: 1. Isi Asumsi | B5: Buka sheet Asumsi. Ganti sel kuning (harga, HPP, bantalan profit, target POAS, ekonomi B2B) dengan angka bisnismu.
A6: 2. Tempel data | B6: Di tiap sheet platform, ganti sel BIRU dengan ekspor akunmu. Baris contoh sudah ada, timpa saja. Ada ruang 30 baris per sheet. Sel hitam adalah rumus, jangan ditimpa.
A7: 3. Baca verdict | B7: Kolom Verdict menilai tiap baris: SCALE, HOLD, FIX, CUT, LOW DATA, atau diagnosis khusus (FATIGUE, FIX LANDING, FIX HOOK, FIX CTA/BODY, CEK MER).
A8: 4. Lihat Dashboard | B8: Ringkasan lintas platform: biaya, ROAS, POAS, MER, baris paling bermasalah, grafik.
A9: 5. Latihan dan agent | B9: Kerjakan sheet Latihan. Lalu lampirkan file ini ke agent dan salin prompt di kolom F (skill digital-ads-ultimate sudah terpasang).
A11: KODE WARNA
A12: Biru | B12: Input atau data yang kamu isi.
A13: Hitam | B13: Rumus. Jangan ditimpa.
A14: Hijau | B14: Tautan dari sheet lain.
A15: Latar kuning | B15: Asumsi kunci yang wajib kamu ganti.
A17: PETA SHEET
A18: Asumsi | B18: Ekonomi per pesanan, target, ambang penilaian, ekonomi B2B, target marketplace.
A19: Google Ads | B19: 6 campaign (Brand, Non-Brand, Kompetitor, PMax, Demand Gen, YouTube) + tabel search terms untuk latihan negative keyword.
A20: Meta Ads | B20: 7 iklan: ada yang fatigue, hook bagus tapi CVR rendah, dan data kurang.
A21: TikTok Ads | B21: 7 kreatif: pemenang Spark, hook lemah, CTA lemah, fatigue.
A22: LinkedIn Ads | B22: 6 campaign B2B sampai SQL dan deal Won: lead murah tapi tidak jadi SQL.
A23: Marketplace | B23: 10 baris Shopee, Tokopedia, TikTok Shop: ROAS tinggi tapi POAS rendah, plus TACoS per platform.
A24: Mingguan | B24: 8 minggu: MER, break-even MER, klaim platform vs omzet nyata, CAC, laba setelah iklan.
A25: Dashboard | B25: Ringkasan dan grafik.
A26: Latihan | B26: 13 tugas dengan kunci jawaban berupa rumus dan prompt siap salin.
A28: METRIK
A29: ROAS | B29: Omzet iklan / biaya iklan. Tidak memperhitungkan HPP, fee, voucher, retur.
A30: POAS | B30: Kontribusi sebelum iklan dari omzet iklan / biaya iklan. Impas di 1,0. POAS = ROAS x margin kontribusi.
A31: MER | B31: Omzet bisnis total / total biaya marketing semua channel.
A32: TACoS | B32: Biaya iklan / omzet total toko (iklan + organik). Untuk marketplace.
A33: Break-even ROAS | B33: 1 / margin kontribusi. Batas bawah ROAS sebelum iklan rugi.
A35: CATATAN PENTING
A36: Data fiktif | B36: Semua angka dan nama produk dibuat untuk latihan, bukan benchmark industri.
A37: Ambang heuristik | B37: Batas hook rate, CTR, CVR, frekuensi, POAS di sheet Asumsi adalah titik awal. Kalibrasi dengan data akunmu sendiri.
A38: Fee marketplace | B38: Komisi dan biaya tetap berubah. Isi dari halaman biaya terbaru di Seller Center.
A39: Verdict bukan perintah | B39: Verdict adalah sinyal awal. Cek lag konversi, volume data, tracking, dan peran campaign sebelum memotong budget.
A40: English | B40: Quick start: replace blue cells with your own exports, set the yellow assumptions, read the Verdict columns and Dashboard, then attach this file to your agent with the prompts in the Latihan sheet (column F, translate or adapt as needed).

Sheet Asumsi
A1: Asumsi dan Ambang Penilaian
A2: Sel biru = input, kuning = asumsi kunci yang WAJIB kamu ganti dengan angka bisnismu. Semua sheet platform membaca dari sini.
A3: EKONOMI PENJUALAN WEBSITE (DTC): dipakai Google, Meta, TikTok
A4: Harga jual rata-rata per pesanan (Rp) | B4: 150000 | C4: Isi harga realisasi, bukan harga coret. Contoh fiktif.
A5: HPP per pesanan (Rp) | B5: 62000 | C5: Harga pokok sampai gudang (produk + inbound + QC).
A6: Biaya payment (% harga) | B6: 0.02 | C6: Gateway, VA, e-wallet.
A7: Subsidi ongkir per pesanan (Rp) | B7: 8000 | C7: Ongkir yang kamu tanggung.
A8: Packaging per pesanan (Rp) | B8: 2000
A9: Cadangan retur/cancel (% harga) | B9: 0.03 | C9: Ambil dari 90 hari terakhir.
A10: Kontribusi per pesanan (Rp) | B10: =B4*(1-B6-B9)-B5-B7-B8 -> 70500 | C10: Rumus. Harga dikurangi biaya variabel.
A11: Margin kontribusi (%) | B11: =B10/B4 -> 0.47 | C11: Rumus.
A12: Break-even ROAS | B12: =1/B11 -> 2.1276596 | C12: Rumus. Di bawah ini iklan rugi di level kontribusi.
A13: Break-even CPA (Rp) | B13: =B10 -> 70500 | C13: Rumus. Pesanan pertama.
A14: Bantalan profit (% dari break-even) | B14: 0.3 | C14: Sisakan untuk overhead dan risiko.
A15: Target CPA (Rp) | B15: =B13*(1-B14) -> 49350 | C15: Rumus.
A16: Target POAS | B16: 1.3 | C16: Heuristik 1,2 sampai 1,5. POAS 1,0 = impas.
A17: Target ROAS | B17: =B12*B16 -> 2.7659574 | C17: Rumus: break-even ROAS x target POAS.
A19: AMBANG PENILAIAN (heuristik, ubah sesuai akunmu)
A20: Minimum konversi/pesanan agar baris dinilai | B20: 5 | C20: Di bawah ini = LOW DATA.
A21: Batas frekuensi Meta prospecting (FATIGUE) | B21: 3 | C21: Heuristik.
A22: Hook rate minimum | B22: 0.25 | C22: Meta: tayang 3 detik / impresi. TikTok: tayang 2 detik / impresi. Heuristik, kalibrasi dengan akunmu.
A23: CTR minimum (link) | B23: 0.008 | C23: Heuristik.
A24: CVR minimum klik ke beli (Meta) | B24: 0.015 | C24: Heuristik.
A25: Rasio CTR sekarang / sebelumnya di bawah ini = FATIGUE | B25: 0.7 | C25: TikTok.
A26: Batas POAS untuk HOLD | B26: 1 | C26: Di atas ini tapi di bawah target = HOLD.
A27: Batas POAS untuk FIX | B27: 0.7 | C27: Di bawah ini = CUT.
A29: EKONOMI B2B (LinkedIn)
A30: Nilai kontrak rata-rata (Rp) | B30: 45000000 | C30: Contoh fiktif: seragam korporat.
A31: Margin kontribusi B2B (%) | B31: 0.3
A32: Kontribusi per deal (Rp) | B32: =B30*B31 -> 13500000 | C32: Rumus.
A33: Rasio SQL ke Won (%) | B33: 0.2 | C33: Ambil dari CRM.
A34: Nilai per SQL (Rp) | B34: =B32*B33 -> 2700000 | C34: Rumus.
A35: Bantalan profit B2B (%) | B35: 0.4
A36: Maksimal biaya per SQL (Rp) | B36: =B34*(1-B35) -> 1620000 | C36: Rumus. Pembanding verdict LinkedIn.
A37: Minimum SQL agar baris dinilai | B37: 3
A39: MARKETPLACE (Shopee, Tokopedia, TikTok Shop)
A40: Target POAS marketplace | B40: 1.3 | C40: Boleh beda dari DTC.
A41: Minimum pesanan agar baris dinilai | B41: 5

Sheet Google Ads
A1: Google Ads: data campaign
A2: September 2026, data FIKTIF untuk latihan. Ganti sel biru dengan ekspor akunmu. Brand contoh: Nusa Apparel (fashion).
A5: TOTAL / RASIO | D5: =SUM(D7:D36) -> 4478000 | E5: =SUM(E7:E36) -> 55700 | F5: =SUM(F7:F36) -> 114150000 | G5: =SUM(G7:G36) -> 1583 | H5: =SUM(H7:H36) -> 237450000 | J5: =IFERROR(E5/D5,"") -> 0.012438589 | K5: =IFERROR(F5/E5,"") -> 2049.3716 | L5: =IFERROR(G5/E5,"") -> 0.028420108 | M5: =IFERROR(F5/G5,"") -> 72109.918 | N5: =IFERROR(H5/F5,"") -> 2.0801577 | P5: =IFERROR(N5*Asumsi!$B$11,"") -> 0.97767411
A6: Campaign | B6: Tipe | C6: Peran (Capture/Create/Defend) | D6: Impresi | E6: Klik | F6: Biaya (Rp) | G6: Konversi | H6: Nilai konversi (Rp) | I6: Porsi konversi brand (opsional, PMax) | J6: CTR | K6: CPC (Rp) | L6: CVR | M6: CPA (Rp) | N6: ROAS | O6: ROAS tanpa brand | P6: POAS | Q6: Verdict | R6: Catatan
A7: Search | Brand | B7: Search | C7: Defend | D7: 48000 | E7: 6200 | F7: 9300000 | G7: 410 | H7: 61500000 | J7: =IF(F7="","",IFERROR(E7/D7,"")) -> 0.12916667 | K7: =IF(F7="","",IFERROR(F7/E7,"")) -> 1500 | L7: =IF(F7="","",IFERROR(G7/E7,"")) -> 0.066129032 | M7: =IF(F7="","",IFERROR(F7/G7,"")) -> 22682.927 | N7: =IF(F7="","",IFERROR(H7/F7,"")) -> 6.6129032 | O7: =IF(F7="","",IF(I7="","",N7*(1-I7))) | P7: =IF(F7="","",IFERROR(N7*Asumsi!$B$11,"")) -> 3.1080645 | Q7: =IF(F7="","",IF(G7<Asumsi!$B$20,"LOW DATA",IF(P7>=Asumsi!$B$16,"SCALE",IF(P7>=Asumsi!$B$26,"HOLD",IF(C7="Create","CEK MER",IF(P7>=Asumsi!$B$27,"FIX","CUT")))))) -> SCALE | R7: ROAS tinggi karena orang sudah cari brand. Jangan jadikan bukti iklan 'menciptakan' demand.
A8: Search | Non-Brand Produk | B8: Search | C8: Capture | D8: 310000 | E8: 9300 | F8: 41850000 | G8: 470 | H8: 70500000 | J8: =IF(F8="","",IFERROR(E8/D8,"")) -> 0.03 | K8: =IF(F8="","",IFERROR(F8/E8,"")) -> 4500 | L8: =IF(F8="","",IFERROR(G8/E8,"")) -> 0.050537634 | M8: =IF(F8="","",IFERROR(F8/G8,"")) -> 89042.553 | N8: =IF(F8="","",IFERROR(H8/F8,"")) -> 1.6845878 | O8: =IF(F8="","",IF(I8="","",N8*(1-I8))) | P8: =IF(F8="","",IFERROR(N8*Asumsi!$B$11,"")) -> 0.79175627 | Q8: =IF(F8="","",IF(G8<Asumsi!$B$20,"LOW DATA",IF(P8>=Asumsi!$B$16,"SCALE",IF(P8>=Asumsi!$B$26,"HOLD",IF(C8="Create","CEK MER",IF(P8>=Asumsi!$B$27,"FIX","CUT")))))) -> FIX | R8: Terbesar di biaya. Cek tabel search terms di bawah untuk pemborosan.
A9: Search | Kompetitor | B9: Search | C9: Capture | D9: 90000 | E9: 1800 | F9: 8100000 | G9: 28 | H9: 4200000 | J9: =IF(F9="","",IFERROR(E9/D9,"")) -> 0.02 | K9: =IF(F9="","",IFERROR(F9/E9,"")) -> 4500 | L9: =IF(F9="","",IFERROR(G9/E9,"")) -> 0.015555556 | M9: =IF(F9="","",IFERROR(F9/G9,"")) -> 289285.71 | N9: =IF(F9="","",IFERROR(H9/F9,"")) -> 0.51851852 | O9: =IF(F9="","",IF(I9="","",N9*(1-I9))) | P9: =IF(F9="","",IFERROR(N9*Asumsi!$B$11,"")) -> 0.2437037 | Q9: =IF(F9="","",IF(G9<Asumsi!$B$20,"LOW DATA",IF(P9>=Asumsi!$B$16,"SCALE",IF(P9>=Asumsi!$B$26,"HOLD",IF(C9="Create","CEK MER",IF(P9>=Asumsi!$B$27,"FIX","CUT")))))) -> CUT | R9: Klik mahal, jarang beli.
A10: PMax | Feed Produk | B10: Performance Max | C10: Capture | D10: 1250000 | E10: 21000 | F10: 36000000 | G10: 520 | H10: 78000000 | I10: 0.38 | J10: =IF(F10="","",IFERROR(E10/D10,"")) -> 0.0168 | K10: =IF(F10="","",IFERROR(F10/E10,"")) -> 1714.2857 | L10: =IF(F10="","",IFERROR(G10/E10,"")) -> 0.024761905 | M10: =IF(F10="","",IFERROR(F10/G10,"")) -> 69230.769 | N10: =IF(F10="","",IFERROR(H10/F10,"")) -> 2.1666667 | O10: =IF(F10="","",IF(I10="","",N10*(1-I10))) -> 1.3433333 | P10: =IF(F10="","",IFERROR(N10*Asumsi!$B$11,"")) -> 1.0183333 | Q10: =IF(F10="","",IF(G10<Asumsi!$B$20,"LOW DATA",IF(P10>=Asumsi!$B$16,"SCALE",IF(P10>=Asumsi!$B$26,"HOLD",IF(C10="Create","CEK MER",IF(P10>=Asumsi!$B$27,"FIX","CUT")))))) -> HOLD | R10: Cek porsi brand: ROAS tanpa brand lebih jujur.
A11: Demand Gen | Prospecting | B11: Demand Gen | C11: Create | D11: 2400000 | E11: 14400 | F11: 14400000 | G11: 60 | H11: 9000000 | J11: =IF(F11="","",IFERROR(E11/D11,"")) -> 0.006 | K11: =IF(F11="","",IFERROR(F11/E11,"")) -> 1000 | L11: =IF(F11="","",IFERROR(G11/E11,"")) -> 0.0041666667 | M11: =IF(F11="","",IFERROR(F11/G11,"")) -> 240000 | N11: =IF(F11="","",IFERROR(H11/F11,"")) -> 0.625 | O11: =IF(F11="","",IF(I11="","",N11*(1-I11))) | P11: =IF(F11="","",IFERROR(N11*Asumsi!$B$11,"")) -> 0.29375 | Q11: =IF(F11="","",IF(G11<Asumsi!$B$20,"LOW DATA",IF(P11>=Asumsi!$B$16,"SCALE",IF(P11>=Asumsi!$B$26,"HOLD",IF(C11="Create","CEK MER",IF(P11>=Asumsi!$B$27,"FIX","CUT")))))) -> CEK MER | R11: Peran Create. Last-click menipu, nilai lewat MER dan brand search.
A12: YouTube | Retargeting Viewer | B12: YouTube | C12: Capture | D12: 380000 | E12: 3000 | F12: 4500000 | G12: 95 | H12: 14250000 | J12: =IF(F12="","",IFERROR(E12/D12,"")) -> 0.0078947368 | K12: =IF(F12="","",IFERROR(F12/E12,"")) -> 1500 | L12: =IF(F12="","",IFERROR(G12/E12,"")) -> 0.031666667 | M12: =IF(F12="","",IFERROR(F12/G12,"")) -> 47368.421 | N12: =IF(F12="","",IFERROR(H12/F12,"")) -> 3.1666667 | O12: =IF(F12="","",IF(I12="","",N12*(1-I12))) | P12: =IF(F12="","",IFERROR(N12*Asumsi!$B$11,"")) -> 1.4883333 | Q12: =IF(F12="","",IF(G12<Asumsi!$B$20,"LOW DATA",IF(P12>=Asumsi!$B$16,"SCALE",IF(P12>=Asumsi!$B$26,"HOLD",IF(C12="Create","CEK MER",IF(P12>=Asumsi!$B$27,"FIX","CUT")))))) -> SCALE | R12: Kecil tapi efisien.
J13: =IF(F13="","",IFERROR(E13/D13,"")) | K13: =IF(F13="","",IFERROR(F13/E13,"")) | L13: =IF(F13="","",IFERROR(G13/E13,"")) | M13: =IF(F13="","",IFERROR(F13/G13,"")) | N13: =IF(F13="","",IFERROR(H13/F13,"")) | O13: =IF(F13="","",IF(I13="","",N13*(1-I13))) | P13: =IF(F13="","",IFERROR(N13*Asumsi!$B$11,"")) | Q13: =IF(F13="","",IF(G13<Asumsi!$B$20,"LOW DATA",IF(P13>=Asumsi!$B$16,"SCALE",IF(P13>=Asumsi!$B$26,"HOLD",IF(C13="Create","CEK MER",IF(P13>=Asumsi!$B$27,"FIX","CUT"))))))
J14: =IF(F14="","",IFERROR(E14/D14,"")) | K14: =IF(F14="","",IFERROR(F14/E14,"")) | L14: =IF(F14="","",IFERROR(G14/E14,"")) | M14: =IF(F14="","",IFERROR(F14/G14,"")) | N14: =IF(F14="","",IFERROR(H14/F14,"")) | O14: =IF(F14="","",IF(I14="","",N14*(1-I14))) | P14: =IF(F14="","",IFERROR(N14*Asumsi!$B$11,"")) | Q14: =IF(F14="","",IF(G14<Asumsi!$B$20,"LOW DATA",IF(P14>=Asumsi!$B$16,"SCALE",IF(P14>=Asumsi!$B$26,"HOLD",IF(C14="Create","CEK MER",IF(P14>=Asumsi!$B$27,"FIX","CUT"))))))
J15: =IF(F15="","",IFERROR(E15/D15,"")) | K15: =IF(F15="","",IFERROR(F15/E15,"")) | L15: =IF(F15="","",IFERROR(G15/E15,"")) | M15: =IF(F15="","",IFERROR(F15/G15,"")) | N15: =IF(F15="","",IFERROR(H15/F15,"")) | O15: =IF(F15="","",IF(I15="","",N15*(1-I15))) | P15: =IF(F15="","",IFERROR(N15*Asumsi!$B$11,"")) | Q15: =IF(F15="","",IF(G15<Asumsi!$B$20,"LOW DATA",IF(P15>=Asumsi!$B$16,"SCALE",IF(P15>=Asumsi!$B$26,"HOLD",IF(C15="Create","CEK MER",IF(P15>=Asumsi!$B$27,"FIX","CUT"))))))
J16: =IF(F16="","",IFERROR(E16/D16,"")) | K16: =IF(F16="","",IFERROR(F16/E16,"")) | L16: =IF(F16="","",IFERROR(G16/E16,"")) | M16: =IF(F16="","",IFERROR(F16/G16,"")) | N16: =IF(F16="","",IFERROR(H16/F16,"")) | O16: =IF(F16="","",IF(I16="","",N16*(1-I16))) | P16: =IF(F16="","",IFERROR(N16*Asumsi!$B$11,"")) | Q16: =IF(F16="","",IF(G16<Asumsi!$B$20,"LOW DATA",IF(P16>=Asumsi!$B$16,"SCALE",IF(P16>=Asumsi!$B$26,"HOLD",IF(C16="Create","CEK MER",IF(P16>=Asumsi!$B$27,"FIX","CUT"))))))
J17: =IF(F17="","",IFERROR(E17/D17,"")) | K17: =IF(F17="","",IFERROR(F17/E17,"")) | L17: =IF(F17="","",IFERROR(G17/E17,"")) | M17: =IF(F17="","",IFERROR(F17/G17,"")) | N17: =IF(F17="","",IFERROR(H17/F17,"")) | O17: =IF(F17="","",IF(I17="","",N17*(1-I17))) | P17: =IF(F17="","",IFERROR(N17*Asumsi!$B$11,"")) | Q17: =IF(F17="","",IF(G17<Asumsi!$B$20,"LOW DATA",IF(P17>=Asumsi!$B$16,"SCALE",IF(P17>=Asumsi!$B$26,"HOLD",IF(C17="Create","CEK MER",IF(P17>=Asumsi!$B$27,"FIX","CUT"))))))
J18: =IF(F18="","",IFERROR(E18/D18,"")) | K18: =IF(F18="","",IFERROR(F18/E18,"")) | L18: =IF(F18="","",IFERROR(G18/E18,"")) | M18: =IF(F18="","",IFERROR(F18/G18,"")) | N18: =IF(F18="","",IFERROR(H18/F18,"")) | O18: =IF(F18="","",IF(I18="","",N18*(1-I18))) | P18: =IF(F18="","",IFERROR(N18*Asumsi!$B$11,"")) | Q18: =IF(F18="","",IF(G18<Asumsi!$B$20,"LOW DATA",IF(P18>=Asumsi!$B$16,"SCALE",IF(P18>=Asumsi!$B$26,"HOLD",IF(C18="Create","CEK MER",IF(P18>=Asumsi!$B$27,"FIX","CUT"))))))
J19: =IF(F19="","",IFERROR(E19/D19,"")) | K19: =IF(F19="","",IFERROR(F19/E19,"")) | L19: =IF(F19="","",IFERROR(G19/E19,"")) | M19: =IF(F19="","",IFERROR(F19/G19,"")) | N19: =IF(F19="","",IFERROR(H19/F19,"")) | O19: =IF(F19="","",IF(I19="","",N19*(1-I19))) | P19: =IF(F19="","",IFERROR(N19*Asumsi!$B$11,"")) | Q19: =IF(F19="","",IF(G19<Asumsi!$B$20,"LOW DATA",IF(P19>=Asumsi!$B$16,"SCALE",IF(P19>=Asumsi!$B$26,"HOLD",IF(C19="Create","CEK MER",IF(P19>=Asumsi!$B$27,"FIX","CUT"))))))
J20: =IF(F20="","",IFERROR(E20/D20,"")) | K20: =IF(F20="","",IFERROR(F20/E20,"")) | L20: =IF(F20="","",IFERROR(G20/E20,"")) | M20: =IF(F20="","",IFERROR(F20/G20,"")) | N20: =IF(F20="","",IFERROR(H20/F20,"")) | O20: =IF(F20="","",IF(I20="","",N20*(1-I20))) | P20: =IF(F20="","",IFERROR(N20*Asumsi!$B$11,"")) | Q20: =IF(F20="","",IF(G20<Asumsi!$B$20,"LOW DATA",IF(P20>=Asumsi!$B$16,"SCALE",IF(P20>=Asumsi!$B$26,"HOLD",IF(C20="Create","CEK MER",IF(P20>=Asumsi!$B$27,"FIX","CUT"))))))
J21: =IF(F21="","",IFERROR(E21/D21,"")) | K21: =IF(F21="","",IFERROR(F21/E21,"")) | L21: =IF(F21="","",IFERROR(G21/E21,"")) | M21: =IF(F21="","",IFERROR(F21/G21,"")) | N21: =IF(F21="","",IFERROR(H21/F21,"")) | O21: =IF(F21="","",IF(I21="","",N21*(1-I21))) | P21: =IF(F21="","",IFERROR(N21*Asumsi!$B$11,"")) | Q21: =IF(F21="","",IF(G21<Asumsi!$B$20,"LOW DATA",IF(P21>=Asumsi!$B$16,"SCALE",IF(P21>=Asumsi!$B$26,"HOLD",IF(C21="Create","CEK MER",IF(P21>=Asumsi!$B$27,"FIX","CUT"))))))
J22: =IF(F22="","",IFERROR(E22/D22,"")) | K22: =IF(F22="","",IFERROR(F22/E22,"")) | L22: =IF(F22="","",IFERROR(G22/E22,"")) | M22: =IF(F22="","",IFERROR(F22/G22,"")) | N22: =IF(F22="","",IFERROR(H22/F22,"")) | O22: =IF(F22="","",IF(I22="","",N22*(1-I22))) | P22: =IF(F22="","",IFERROR(N22*Asumsi!$B$11,"")) | Q22: =IF(F22="","",IF(G22<Asumsi!$B$20,"LOW DATA",IF(P22>=Asumsi!$B$16,"SCALE",IF(P22>=Asumsi!$B$26,"HOLD",IF(C22="Create","CEK MER",IF(P22>=Asumsi!$B$27,"FIX","CUT"))))))
J23: =IF(F23="","",IFERROR(E23/D23,"")) | K23: =IF(F23="","",IFERROR(F23/E23,"")) | L23: =IF(F23="","",IFERROR(G23/E23,"")) | M23: =IF(F23="","",IFERROR(F23/G23,"")) | N23: =IF(F23="","",IFERROR(H23/F23,"")) | O23: =IF(F23="","",IF(I23="","",N23*(1-I23))) | P23: =IF(F23="","",IFERROR(N23*Asumsi!$B$11,"")) | Q23: =IF(F23="","",IF(G23<Asumsi!$B$20,"LOW DATA",IF(P23>=Asumsi!$B$16,"SCALE",IF(P23>=Asumsi!$B$26,"HOLD",IF(C23="Create","CEK MER",IF(P23>=Asumsi!$B$27,"FIX","CUT"))))))
J24: =IF(F24="","",IFERROR(E24/D24,"")) | K24: =IF(F24="","",IFERROR(F24/E24,"")) | L24: =IF(F24="","",IFERROR(G24/E24,"")) | M24: =IF(F24="","",IFERROR(F24/G24,"")) | N24: =IF(F24="","",IFERROR(H24/F24,"")) | O24: =IF(F24="","",IF(I24="","",N24*(1-I24))) | P24: =IF(F24="","",IFERROR(N24*Asumsi!$B$11,"")) | Q24: =IF(F24="","",IF(G24<Asumsi!$B$20,"LOW DATA",IF(P24>=Asumsi!$B$16,"SCALE",IF(P24>=Asumsi!$B$26,"HOLD",IF(C24="Create","CEK MER",IF(P24>=Asumsi!$B$27,"FIX","CUT"))))))
... J36: =IF(F36="","",IFERROR(E36/D36,"")) | K36: =IF(F36="","",IFERROR(F36/E36,"")) | L36: =IF(F36="","",IFERROR(G36/E36,"")) | M36: =IF(F36="","",IFERROR(F36/G36,"")) | N36: =IF(F36="","",IFERROR(H36/F36,"")) | O36: =IF(F36="","",IF(I36="","",N36*(1-I36))) | P36: =IF(F36="","",IFERROR(N36*Asumsi!$B$11,"")) | Q36: =IF(F36="","",IF(G36<Asumsi!$B$20,"LOW DATA",IF(P36>=Asumsi!$B$16,"SCALE",IF(P36>=Asumsi!$B$26,"HOLD",IF(C36="Create","CEK MER",IF(P36>=Asumsi!$B$27,"FIX","CUT"))))))
A39: SEARCH TERMS: latihan negative keyword
A41: Search term | B41: Campaign | C41: Klik | D41: Biaya (Rp) | E41: Konversi | F41: CPC (Rp) | G41: CPA (Rp) | H41: Saran aksi
A42: kaos polos premium | B42: Search | Non-Brand Produk | C42: 820 | D42: 3690000 | E42: 41 | F42: =IF(A42="","",IFERROR(D42/C42,"")) -> 4500 | G42: =IF(A42="","",IFERROR(D42/E42,"")) -> 90000 | H42: =IF(A42="","",IF(AND(E42=0,D42>=2*Asumsi!$B$15),"TAMBAH NEGATIF",IF(E42=0,"PANTAU",IF(G42<=Asumsi!$B$15,"PROMOSI KE EXACT",IF(G42>2*Asumsi!$B$15,"TURUNKAN / PINDAH PHRASE","PANTAU"))))) -> PANTAU
A43: kaos polos murah | B43: Search | Non-Brand Produk | C43: 1400 | D43: 5600000 | E43: 18 | F43: =IF(A43="","",IFERROR(D43/C43,"")) -> 4000 | G43: =IF(A43="","",IFERROR(D43/E43,"")) -> 311111.11 | H43: =IF(A43="","",IF(AND(E43=0,D43>=2*Asumsi!$B$15),"TAMBAH NEGATIF",IF(E43=0,"PANTAU",IF(G43<=Asumsi!$B$15,"PROMOSI KE EXACT",IF(G43>2*Asumsi!$B$15,"TURUNKAN / PINDAH PHRASE","PANTAU"))))) -> TURUNKAN / PINDAH PHRASE
A44: grosir kaos polos | B44: Search | Non-Brand Produk | C44: 300 | D44: 1350000 | E44: 22 | F44: =IF(A44="","",IFERROR(D44/C44,"")) -> 4500 | G44: =IF(A44="","",IFERROR(D44/E44,"")) -> 61363.636 | H44: =IF(A44="","",IF(AND(E44=0,D44>=2*Asumsi!$B$15),"TAMBAH NEGATIF",IF(E44=0,"PANTAU",IF(G44<=Asumsi!$B$15,"PROMOSI KE EXACT",IF(G44>2*Asumsi!$B$15,"TURUNKAN / PINDAH PHRASE","PANTAU"))))) -> PANTAU
A45: cara membuat kaos sablon sendiri | B45: Search | Non-Brand Produk | C45: 640 | D45: 2400000 | E45: 0 | F45: =IF(A45="","",IFERROR(D45/C45,"")) -> 3750 | G45: =IF(A45="","",IFERROR(D45/E45,"")) | H45: =IF(A45="","",IF(AND(E45=0,D45>=2*Asumsi!$B$15),"TAMBAH NEGATIF",IF(E45=0,"PANTAU",IF(G45<=Asumsi!$B$15,"PROMOSI KE EXACT",IF(G45>2*Asumsi!$B$15,"TURUNKAN / PINDAH PHRASE","PANTAU"))))) -> TAMBAH NEGATIF
A46: lowongan konveksi | B46: Search | Non-Brand Produk | C46: 210 | D46: 900000 | E46: 0 | F46: =IF(A46="","",IFERROR(D46/C46,"")) -> 4285.7143 | G46: =IF(A46="","",IFERROR(D46/E46,"")) | H46: =IF(A46="","",IF(AND(E46=0,D46>=2*Asumsi!$B$15),"TAMBAH NEGATIF",IF(E46=0,"PANTAU",IF(G46<=Asumsi!$B$15,"PROMOSI KE EXACT",IF(G46>2*Asumsi!$B$15,"TURUNKAN / PINDAH PHRASE","PANTAU"))))) -> TAMBAH NEGATIF
A47: template desain kaos gratis | B47: Search | Non-Brand Produk | C47: 380 | D47: 1500000 | E47: 0 | F47: =IF(A47="","",IFERROR(D47/C47,"")) -> 3947.3684 | G47: =IF(A47="","",IFERROR(D47/E47,"")) | H47: =IF(A47="","",IF(AND(E47=0,D47>=2*Asumsi!$B$15),"TAMBAH NEGATIF",IF(E47=0,"PANTAU",IF(G47<=Asumsi!$B$15,"PROMOSI KE EXACT",IF(G47>2*Asumsi!$B$15,"TURUNKAN / PINDAH PHRASE","PANTAU"))))) -> TAMBAH NEGATIF
A48: hoodie oversize pria | B48: Search | Non-Brand Produk | C48: 520 | D48: 2340000 | E48: 38 | F48: =IF(A48="","",IFERROR(D48/C48,"")) -> 4500 | G48: =IF(A48="","",IFERROR(D48/E48,"")) -> 61578.947 | H48: =IF(A48="","",IF(AND(E48=0,D48>=2*Asumsi!$B$15),"TAMBAH NEGATIF",IF(E48=0,"PANTAU",IF(G48<=Asumsi!$B$15,"PROMOSI KE EXACT",IF(G48>2*Asumsi!$B$15,"TURUNKAN / PINDAH PHRASE","PANTAU"))))) -> PANTAU
A49: hoodie oversize polos hitam | B49: Search | Non-Brand Produk | C49: 260 | D49: 1100000 | E49: 33 | F49: =IF(A49="","",IFERROR(D49/C49,"")) -> 4230.7692 | G49: =IF(A49="","",IFERROR(D49/E49,"")) -> 33333.333 | H49: =IF(A49="","",IF(AND(E49=0,D49>=2*Asumsi!$B$15),"TAMBAH NEGATIF",IF(E49=0,"PANTAU",IF(G49<=Asumsi!$B$15,"PROMOSI KE EXACT",IF(G49>2*Asumsi!$B$15,"TURUNKAN / PINDAH PHRASE","PANTAU"))))) -> PROMOSI KE EXACT
A50: kaos polos cotton combed 30s | B50: Search | Non-Brand Produk | C50: 180 | D50: 720000 | E50: 20 | F50: =IF(A50="","",IFERROR(D50/C50,"")) -> 4000 | G50: =IF(A50="","",IFERROR(D50/E50,"")) -> 36000 | H50: =IF(A50="","",IF(AND(E50=0,D50>=2*Asumsi!$B$15),"TAMBAH NEGATIF",IF(E50=0,"PANTAU",IF(G50<=Asumsi!$B$15,"PROMOSI KE EXACT",IF(G50>2*Asumsi!$B$15,"TURUNKAN / PINDAH PHRASE","PANTAU"))))) -> PROMOSI KE EXACT
A51: jasa sablon kaos satuan | B51: Search | Non-Brand Produk | C51: 450 | D51: 2100000 | E51: 3 | F51: =IF(A51="","",IFERROR(D51/C51,"")) -> 4666.6667 | G51: =IF(A51="","",IFERROR(D51/E51,"")) -> 700000 | H51: =IF(A51="","",IF(AND(E51=0,D51>=2*Asumsi!$B$15),"TAMBAH NEGATIF",IF(E51=0,"PANTAU",IF(G51<=Asumsi!$B$15,"PROMOSI KE EXACT",IF(G51>2*Asumsi!$B$15,"TURUNKAN / PINDAH PHRASE","PANTAU"))))) -> TURUNKAN / PINDAH PHRASE
F52: =IF(A52="","",IFERROR(D52/C52,"")) | G52: =IF(A52="","",IFERROR(D52/E52,"")) | H52: =IF(A52="","",IF(AND(E52=0,D52>=2*Asumsi!$B$15),"TAMBAH NEGATIF",IF(E52=0,"PANTAU",IF(G52<=Asumsi!$B$15,"PROMOSI KE EXACT",IF(G52>2*Asumsi!$B$15,"TURUNKAN / PINDAH PHRASE","PANTAU")))))
F53: =IF(A53="","",IFERROR(D53/C53,"")) | G53: =IF(A53="","",IFERROR(D53/E53,"")) | H53: =IF(A53="","",IF(AND(E53=0,D53>=2*Asumsi!$B$15),"TAMBAH NEGATIF",IF(E53=0,"PANTAU",IF(G53<=Asumsi!$B$15,"PROMOSI KE EXACT",IF(G53>2*Asumsi!$B$15,"TURUNKAN / PINDAH PHRASE","PANTAU")))))
F54: =IF(A54="","",IFERROR(D54/C54,"")) | G54: =IF(A54="","",IFERROR(D54/E54,"")) | H54: =IF(A54="","",IF(AND(E54=0,D54>=2*Asumsi!$B$15),"TAMBAH NEGATIF",IF(E54=0,"PANTAU",IF(G54<=Asumsi!$B$15,"PROMOSI KE EXACT",IF(G54>2*Asumsi!$B$15,"TURUNKAN / PINDAH PHRASE","PANTAU")))))
F55: =IF(A55="","",IFERROR(D55/C55,"")) | G55: =IF(A55="","",IFERROR(D55/E55,"")) | H55: =IF(A55="","",IF(AND(E55=0,D55>=2*Asumsi!$B$15),"TAMBAH NEGATIF",IF(E55=0,"PANTAU",IF(G55<=Asumsi!$B$15,"PROMOSI KE EXACT",IF(G55>2*Asumsi!$B$15,"TURUNKAN / PINDAH PHRASE","PANTAU")))))
A57: Aturan saran: negatif jika 0 konversi dan biaya >= 2x target CPA. Promosi ke exact jika CPA <= target CPA. Turunkan jika CPA > 2x target. Heuristik.

Sheet Meta Ads
A1: Meta Ads: data per iklan (kreatif)
A2: September 2026, data FIKTIF. PROSP = prospecting, RET = retargeting. Kosongkan 3s views untuk iklan gambar.
A5: TOTAL / RASIO | D5: =SUM(D7:D36) -> 43200000 | E5: =SUM(E7:E36) -> 1946000 | H5: =SUM(H7:H36) -> 23340 | I5: =SUM(I7:I36) -> 1990 | J5: =SUM(J7:J36) -> 650 | K5: =SUM(K7:K36) -> 91800000 | L5: =IFERROR(D5/E5*1000,"") -> 22199.383 | O5: =IFERROR(H5/E5,"") -> 0.011993834 | P5: =IFERROR(D5/H5,"") -> 1850.8997 | Q5: =IFERROR(J5/H5,"") -> 0.027849186 | R5: =IFERROR(D5/J5,"") -> 66461.538 | S5: =IFERROR(K5/D5,"") -> 2.125 | T5: =IFERROR(S5*Asumsi!$B$11,"") -> 0.99875
A6: Iklan / Kreatif | B6: Campaign (PROSP/RET) | C6: Format | D6: Biaya (Rp) | E6: Impresi | F6: Jangkauan | G6: Tayang 3 detik | H6: Klik link | I6: Add to cart | J6: Pembelian | K6: Omzet (Rp) | L6: CPM (Rp) | M6: Frekuensi | N6: Hook rate | O6: CTR link | P6: CPC (Rp) | Q6: CVR klik-beli | R6: CPA (Rp) | S6: ROAS | T6: POAS | U6: Verdict
A7: UGC Pain Hook v1 | B7: PROSP | C7: Reels 9:16 | D7: 12000000 | E7: 540000 | F7: 380000 | G7: 183600 | H7: 7020 | I7: 560 | J7: 190 | K7: 28500000 | L7: =IF(D7="","",IFERROR(D7/E7*1000,"")) -> 22222.222 | M7: =IF(D7="","",IFERROR(E7/F7,"")) -> 1.4210526 | N7: =IF(D7="","",IF(G7="","",IFERROR(G7/E7,""))) -> 0.34 | O7: =IF(D7="","",IFERROR(H7/E7,"")) -> 0.013 | P7: =IF(D7="","",IFERROR(D7/H7,"")) -> 1709.4017 | Q7: =IF(D7="","",IFERROR(J7/H7,"")) -> 0.027065527 | R7: =IF(D7="","",IFERROR(D7/J7,"")) -> 63157.895 | S7: =IF(D7="","",IFERROR(K7/D7,"")) -> 2.375 | T7: =IF(D7="","",IFERROR(S7*Asumsi!$B$11,"")) -> 1.11625 | U7: =IF(D7="","",IF(J7<Asumsi!$B$20,"LOW DATA",IF(AND(B7="PROSP",ISNUMBER(M7),M7>=Asumsi!$B$21),"FATIGUE",IF(AND(ISNUMBER(N7),N7>=Asumsi!$B$22,ISNUMBER(Q7),Q7<Asumsi!$B$24),"FIX LANDING",IF(T7>=Asumsi!$B$16,"SCALE",IF(T7>=Asumsi!$B$26,"HOLD",IF(T7>=Asumsi!$B$27,"FIX","CUT"))))))) -> HOLD
A8: Demo Comparison v1 | B8: PROSP | C8: Reels 9:16 | D8: 9000000 | E8: 380000 | F8: 290000 | G8: 98800 | H8: 4560 | I8: 400 | J8: 150 | K8: 22500000 | L8: =IF(D8="","",IFERROR(D8/E8*1000,"")) -> 23684.211 | M8: =IF(D8="","",IFERROR(E8/F8,"")) -> 1.3103448 | N8: =IF(D8="","",IF(G8="","",IFERROR(G8/E8,""))) -> 0.26 | O8: =IF(D8="","",IFERROR(H8/E8,"")) -> 0.012 | P8: =IF(D8="","",IFERROR(D8/H8,"")) -> 1973.6842 | Q8: =IF(D8="","",IFERROR(J8/H8,"")) -> 0.032894737 | R8: =IF(D8="","",IFERROR(D8/J8,"")) -> 60000 | S8: =IF(D8="","",IFERROR(K8/D8,"")) -> 2.5 | T8: =IF(D8="","",IFERROR(S8*Asumsi!$B$11,"")) -> 1.175 | U8: =IF(D8="","",IF(J8<Asumsi!$B$20,"LOW DATA",IF(AND(B8="PROSP",ISNUMBER(M8),M8>=Asumsi!$B$21),"FATIGUE",IF(AND(ISNUMBER(N8),N8>=Asumsi!$B$22,ISNUMBER(Q8),Q8<Asumsi!$B$24),"FIX LANDING",IF(T8>=Asumsi!$B$16,"SCALE",IF(T8>=Asumsi!$B$26,"HOLD",IF(T8>=Asumsi!$B$27,"FIX","CUT"))))))) -> HOLD
A9: UGC Pain Hook v0 (lama) | B9: PROSP | C9: Reels 9:16 | D9: 7500000 | E9: 336000 | F9: 80000 | G9: 60480 | H9: 1680 | I9: 90 | J9: 28 | K9: 4200000 | L9: =IF(D9="","",IFERROR(D9/E9*1000,"")) -> 22321.429 | M9: =IF(D9="","",IFERROR(E9/F9,"")) -> 4.2 | N9: =IF(D9="","",IF(G9="","",IFERROR(G9/E9,""))) -> 0.18 | O9: =IF(D9="","",IFERROR(H9/E9,"")) -> 0.005 | P9: =IF(D9="","",IFERROR(D9/H9,"")) -> 4464.2857 | Q9: =IF(D9="","",IFERROR(J9/H9,"")) -> 0.016666667 | R9: =IF(D9="","",IFERROR(D9/J9,"")) -> 267857.14 | S9: =IF(D9="","",IFERROR(K9/D9,"")) -> 0.56 | T9: =IF(D9="","",IFERROR(S9*Asumsi!$B$11,"")) -> 0.2632 | U9: =IF(D9="","",IF(J9<Asumsi!$B$20,"LOW DATA",IF(AND(B9="PROSP",ISNUMBER(M9),M9>=Asumsi!$B$21),"FATIGUE",IF(AND(ISNUMBER(N9),N9>=Asumsi!$B$22,ISNUMBER(Q9),Q9<Asumsi!$B$24),"FIX LANDING",IF(T9>=Asumsi!$B$16,"SCALE",IF(T9>=Asumsi!$B$26,"HOLD",IF(T9>=Asumsi!$B$27,"FIX","CUT"))))))) -> FATIGUE
A10: Founder Story | B10: PROSP | C10: Video 4:5 | D10: 3000000 | E10: 150000 | F10: 120000 | G10: 54000 | H10: 2250 | I10: 50 | J10: 9 | K10: 1350000 | L10: =IF(D10="","",IFERROR(D10/E10*1000,"")) -> 20000 | M10: =IF(D10="","",IFERROR(E10/F10,"")) -> 1.25 | N10: =IF(D10="","",IF(G10="","",IFERROR(G10/E10,""))) -> 0.36 | O10: =IF(D10="","",IFERROR(H10/E10,"")) -> 0.015 | P10: =IF(D10="","",IFERROR(D10/H10,"")) -> 1333.3333 | Q10: =IF(D10="","",IFERROR(J10/H10,"")) -> 0.004 | R10: =IF(D10="","",IFERROR(D10/J10,"")) -> 333333.33 | S10: =IF(D10="","",IFERROR(K10/D10,"")) -> 0.45 | T10: =IF(D10="","",IFERROR(S10*Asumsi!$B$11,"")) -> 0.2115 | U10: =IF(D10="","",IF(J10<Asumsi!$B$20,"LOW DATA",IF(AND(B10="PROSP",ISNUMBER(M10),M10>=Asumsi!$B$21),"FATIGUE",IF(AND(ISNUMBER(N10),N10>=Asumsi!$B$22,ISNUMBER(Q10),Q10<Asumsi!$B$24),"FIX LANDING",IF(T10>=Asumsi!$B$16,"SCALE",IF(T10>=Asumsi!$B$26,"HOLD",IF(T10>=Asumsi!$B$27,"FIX","CUT"))))))) -> FIX LANDING
A11: Testimonial Static | B11: PROSP | C11: Gambar 4:5 | D11: 6000000 | E11: 300000 | F11: 158000 | H11: 3300 | I11: 270 | J11: 110 | K11: 10800000 | L11: =IF(D11="","",IFERROR(D11/E11*1000,"")) -> 20000 | M11: =IF(D11="","",IFERROR(E11/F11,"")) -> 1.8987342 | N11: =IF(D11="","",IF(G11="","",IFERROR(G11/E11,""))) | O11: =IF(D11="","",IFERROR(H11/E11,"")) -> 0.011 | P11: =IF(D11="","",IFERROR(D11/H11,"")) -> 1818.1818 | Q11: =IF(D11="","",IFERROR(J11/H11,"")) -> 0.033333333 | R11: =IF(D11="","",IFERROR(D11/J11,"")) -> 54545.455 | S11: =IF(D11="","",IFERROR(K11/D11,"")) -> 1.8 | T11: =IF(D11="","",IFERROR(S11*Asumsi!$B$11,"")) -> 0.846 | U11: =IF(D11="","",IF(J11<Asumsi!$B$20,"LOW DATA",IF(AND(B11="PROSP",ISNUMBER(M11),M11>=Asumsi!$B$21),"FATIGUE",IF(AND(ISNUMBER(N11),N11>=Asumsi!$B$22,ISNUMBER(Q11),Q11<Asumsi!$B$24),"FIX LANDING",IF(T11>=Asumsi!$B$16,"SCALE",IF(T11>=Asumsi!$B$26,"HOLD",IF(T11>=Asumsi!$B$27,"FIX","CUT"))))))) -> FIX
A12: Cart Abandoner 7 hari | B12: RET | C12: Carousel | D12: 5000000 | E12: 210000 | F12: 75000 | G12: 50400 | H12: 4200 | I12: 600 | J12: 160 | K12: 24000000 | L12: =IF(D12="","",IFERROR(D12/E12*1000,"")) -> 23809.524 | M12: =IF(D12="","",IFERROR(E12/F12,"")) -> 2.8 | N12: =IF(D12="","",IF(G12="","",IFERROR(G12/E12,""))) -> 0.24 | O12: =IF(D12="","",IFERROR(H12/E12,"")) -> 0.02 | P12: =IF(D12="","",IFERROR(D12/H12,"")) -> 1190.4762 | Q12: =IF(D12="","",IFERROR(J12/H12,"")) -> 0.038095238 | R12: =IF(D12="","",IFERROR(D12/J12,"")) -> 31250 | S12: =IF(D12="","",IFERROR(K12/D12,"")) -> 4.8 | T12: =IF(D12="","",IFERROR(S12*Asumsi!$B$11,"")) -> 2.256 | U12: =IF(D12="","",IF(J12<Asumsi!$B$20,"LOW DATA",IF(AND(B12="PROSP",ISNUMBER(M12),M12>=Asumsi!$B$21),"FATIGUE",IF(AND(ISNUMBER(N12),N12>=Asumsi!$B$22,ISNUMBER(Q12),Q12<Asumsi!$B$24),"FIX LANDING",IF(T12>=Asumsi!$B$16,"SCALE",IF(T12>=Asumsi!$B$26,"HOLD",IF(T12>=Asumsi!$B$27,"FIX","CUT"))))))) -> SCALE
A13: Carousel Bundle Hemat (tes baru) | B13: PROSP | C13: Carousel | D13: 700000 | E13: 30000 | F13: 26000 | G13: 7500 | H13: 330 | I13: 20 | J13: 3 | K13: 450000 | L13: =IF(D13="","",IFERROR(D13/E13*1000,"")) -> 23333.333 | M13: =IF(D13="","",IFERROR(E13/F13,"")) -> 1.1538462 | N13: =IF(D13="","",IF(G13="","",IFERROR(G13/E13,""))) -> 0.25 | O13: =IF(D13="","",IFERROR(H13/E13,"")) -> 0.011 | P13: =IF(D13="","",IFERROR(D13/H13,"")) -> 2121.2121 | Q13: =IF(D13="","",IFERROR(J13/H13,"")) -> 0.0090909091 | R13: =IF(D13="","",IFERROR(D13/J13,"")) -> 233333.33 | S13: =IF(D13="","",IFERROR(K13/D13,"")) -> 0.64285714 | T13: =IF(D13="","",IFERROR(S13*Asumsi!$B$11,"")) -> 0.30214286 | U13: =IF(D13="","",IF(J13<Asumsi!$B$20,"LOW DATA",IF(AND(B13="PROSP",ISNUMBER(M13),M13>=Asumsi!$B$21),"FATIGUE",IF(AND(ISNUMBER(N13),N13>=Asumsi!$B$22,ISNUMBER(Q13),Q13<Asumsi!$B$24),"FIX LANDING",IF(T13>=Asumsi!$B$16,"SCALE",IF(T13>=Asumsi!$B$26,"HOLD",IF(T13>=Asumsi!$B$27,"FIX","CUT"))))))) -> LOW DATA
L14: =IF(D14="","",IFERROR(D14/E14*1000,"")) | M14: =IF(D14="","",IFERROR(E14/F14,"")) | N14: =IF(D14="","",IF(G14="","",IFERROR(G14/E14,""))) | O14: =IF(D14="","",IFERROR(H14/E14,"")) | P14: =IF(D14="","",IFERROR(D14/H14,"")) | Q14: =IF(D14="","",IFERROR(J14/H14,"")) | R14: =IF(D14="","",IFERROR(D14/J14,"")) | S14: =IF(D14="","",IFERROR(K14/D14,"")) | T14: =IF(D14="","",IFERROR(S14*Asumsi!$B$11,"")) | U14: =IF(D14="","",IF(J14<Asumsi!$B$20,"LOW DATA",IF(AND(B14="PROSP",ISNUMBER(M14),M14>=Asumsi!$B$21),"FATIGUE",IF(AND(ISNUMBER(N14),N14>=Asumsi!$B$22,ISNUMBER(Q14),Q14<Asumsi!$B$24),"FIX LANDING",IF(T14>=Asumsi!$B$16,"SCALE",IF(T14>=Asumsi!$B$26,"HOLD",IF(T14>=Asumsi!$B$27,"FIX","CUT")))))))
L15: =IF(D15="","",IFERROR(D15/E15*1000,"")) | M15: =IF(D15="","",IFERROR(E15/F15,"")) | N15: =IF(D15="","",IF(G15="","",IFERROR(G15/E15,""))) | O15: =IF(D15="","",IFERROR(H15/E15,"")) | P15: =IF(D15="","",IFERROR(D15/H15,"")) | Q15: =IF(D15="","",IFERROR(J15/H15,"")) | R15: =IF(D15="","",IFERROR(D15/J15,"")) | S15: =IF(D15="","",IFERROR(K15/D15,"")) | T15: =IF(D15="","",IFERROR(S15*Asumsi!$B$11,"")) | U15: =IF(D15="","",IF(J15<Asumsi!$B$20,"LOW DATA",IF(AND(B15="PROSP",ISNUMBER(M15),M15>=Asumsi!$B$21),"FATIGUE",IF(AND(ISNUMBER(N15),N15>=Asumsi!$B$22,ISNUMBER(Q15),Q15<Asumsi!$B$24),"FIX LANDING",IF(T15>=Asumsi!$B$16,"SCALE",IF(T15>=Asumsi!$B$26,"HOLD",IF(T15>=Asumsi!$B$27,"FIX","CUT")))))))
L16: =IF(D16="","",IFERROR(D16/E16*1000,"")) | M16: =IF(D16="","",IFERROR(E16/F16,"")) | N16: =IF(D16="","",IF(G16="","",IFERROR(G16/E16,""))) | O16: =IF(D16="","",IFERROR(H16/E16,"")) | P16: =IF(D16="","",IFERROR(D16/H16,"")) | Q16: =IF(D16="","",IFERROR(J16/H16,"")) | R16: =IF(D16="","",IFERROR(D16/J16,"")) | S16: =IF(D16="","",IFERROR(K16/D16,"")) | T16: =IF(D16="","",IFERROR(S16*Asumsi!$B$11,"")) | U16: =IF(D16="","",IF(J16<Asumsi!$B$20,"LOW DATA",IF(AND(B16="PROSP",ISNUMBER(M16),M16>=Asumsi!$B$21),"FATIGUE",IF(AND(ISNUMBER(N16),N16>=Asumsi!$B$22,ISNUMBER(Q16),Q16<Asumsi!$B$24),"FIX LANDING",IF(T16>=Asumsi!$B$16,"SCALE",IF(T16>=Asumsi!$B$26,"HOLD",IF(T16>=Asumsi!$B$27,"FIX","CUT")))))))
L17: =IF(D17="","",IFERROR(D17/E17*1000,"")) | M17: =IF(D17="","",IFERROR(E17/F17,"")) | N17: =IF(D17="","",IF(G17="","",IFERROR(G17/E17,""))) | O17: =IF(D17="","",IFERROR(H17/E17,"")) | P17: =IF(D17="","",IFERROR(D17/H17,"")) | Q17: =IF(D17="","",IFERROR(J17/H17,"")) | R17: =IF(D17="","",IFERROR(D17/J17,"")) | S17: =IF(D17="","",IFERROR(K17/D17,"")) | T17: =IF(D17="","",IFERROR(S17*Asumsi!$B$11,"")) | U17: =IF(D17="","",IF(J17<Asumsi!$B$20,"LOW DATA",IF(AND(B17="PROSP",ISNUMBER(M17),M17>=Asumsi!$B$21),"FATIGUE",IF(AND(ISNUMBER(N17),N17>=Asumsi!$B$22,ISNUMBER(Q17),Q17<Asumsi!$B$24),"FIX LANDING",IF(T17>=Asumsi!$B$16,"SCALE",IF(T17>=Asumsi!$B$26,"HOLD",IF(T17>=Asumsi!$B$27,"FIX","CUT")))))))
L18: =IF(D18="","",IFERROR(D18/E18*1000,"")) | M18: =IF(D18="","",IFERROR(E18/F18,"")) | N18: =IF(D18="","",IF(G18="","",IFERROR(G18/E18,""))) | O18: =IF(D18="","",IFERROR(H18/E18,"")) | P18: =IF(D18="","",IFERROR(D18/H18,"")) | Q18: =IF(D18="","",IFERROR(J18/H18,"")) | R18: =IF(D18="","",IFERROR(D18/J18,"")) | S18: =IF(D18="","",IFERROR(K18/D18,"")) | T18: =IF(D18="","",IFERROR(S18*Asumsi!$B$11,"")) | U18: =IF(D18="","",IF(J18<Asumsi!$B$20,"LOW DATA",IF(AND(B18="PROSP",ISNUMBER(M18),M18>=Asumsi!$B$21),"FATIGUE",IF(AND(ISNUMBER(N18),N18>=Asumsi!$B$22,ISNUMBER(Q18),Q18<Asumsi!$B$24),"FIX LANDING",IF(T18>=Asumsi!$B$16,"SCALE",IF(T18>=Asumsi!$B$26,"HOLD",IF(T18>=Asumsi!$B$27,"FIX","CUT")))))))
L19: =IF(D19="","",IFERROR(D19/E19*1000,"")) | M19: =IF(D19="","",IFERROR(E19/F19,"")) | N19: =IF(D19="","",IF(G19="","",IFERROR(G19/E19,""))) | O19: =IF(D19="","",IFERROR(H19/E19,"")) | P19: =IF(D19="","",IFERROR(D19/H19,"")) | Q19: =IF(D19="","",IFERROR(J19/H19,"")) | R19: =IF(D19="","",IFERROR(D19/J19,"")) | S19: =IF(D19="","",IFERROR(K19/D19,"")) | T19: =IF(D19="","",IFERROR(S19*Asumsi!$B$11,"")) | U19: =IF(D19="","",IF(J19<Asumsi!$B$20,"LOW DATA",IF(AND(B19="PROSP",ISNUMBER(M19),M19>=Asumsi!$B$21),"FATIGUE",IF(AND(ISNUMBER(N19),N19>=Asumsi!$B$22,ISNUMBER(Q19),Q19<Asumsi!$B$24),"FIX LANDING",IF(T19>=Asumsi!$B$16,"SCALE",IF(T19>=Asumsi!$B$26,"HOLD",IF(T19>=Asumsi!$B$27,"FIX","CUT")))))))
L20: =IF(D20="","",IFERROR(D20/E20*1000,"")) | M20: =IF(D20="","",IFERROR(E20/F20,"")) | N20: =IF(D20="","",IF(G20="","",IFERROR(G20/E20,""))) | O20: =IF(D20="","",IFERROR(H20/E20,"")) | P20: =IF(D20="","",IFERROR(D20/H20,"")) | Q20: =IF(D20="","",IFERROR(J20/H20,"")) | R20: =IF(D20="","",IFERROR(D20/J20,"")) | S20: =IF(D20="","",IFERROR(K20/D20,"")) | T20: =IF(D20="","",IFERROR(S20*Asumsi!$B$11,"")) | U20: =IF(D20="","",IF(J20<Asumsi!$B$20,"LOW DATA",IF(AND(B20="PROSP",ISNUMBER(M20),M20>=Asumsi!$B$21),"FATIGUE",IF(AND(ISNUMBER(N20),N20>=Asumsi!$B$22,ISNUMBER(Q20),Q20<Asumsi!$B$24),"FIX LANDING",IF(T20>=Asumsi!$B$16,"SCALE",IF(T20>=Asumsi!$B$26,"HOLD",IF(T20>=Asumsi!$B$27,"FIX","CUT")))))))
L21: =IF(D21="","",IFERROR(D21/E21*1000,"")) | M21: =IF(D21="","",IFERROR(E21/F21,"")) | N21: =IF(D21="","",IF(G21="","",IFERROR(G21/E21,""))) | O21: =IF(D21="","",IFERROR(H21/E21,"")) | P21: =IF(D21="","",IFERROR(D21/H21,"")) | Q21: =IF(D21="","",IFERROR(J21/H21,"")) | R21: =IF(D21="","",IFERROR(D21/J21,"")) | S21: =IF(D21="","",IFERROR(K21/D21,"")) | T21: =IF(D21="","",IFERROR(S21*Asumsi!$B$11,"")) | U21: =IF(D21="","",IF(J21<Asumsi!$B$20,"LOW DATA",IF(AND(B21="PROSP",ISNUMBER(M21),M21>=Asumsi!$B$21),"FATIGUE",IF(AND(ISNUMBER(N21),N21>=Asumsi!$B$22,ISNUMBER(Q21),Q21<Asumsi!$B$24),"FIX LANDING",IF(T21>=Asumsi!$B$16,"SCALE",IF(T21>=Asumsi!$B$26,"HOLD",IF(T21>=Asumsi!$B$27,"FIX","CUT")))))))
L22: =IF(D22="","",IFERROR(D22/E22*1000,"")) | M22: =IF(D22="","",IFERROR(E22/F22,"")) | N22: =IF(D22="","",IF(G22="","",IFERROR(G22/E22,""))) | O22: =IF(D22="","",IFERROR(H22/E22,"")) | P22: =IF(D22="","",IFERROR(D22/H22,"")) | Q22: =IF(D22="","",IFERROR(J22/H22,"")) | R22: =IF(D22="","",IFERROR(D22/J22,"")) | S22: =IF(D22="","",IFERROR(K22/D22,"")) | T22: =IF(D22="","",IFERROR(S22*Asumsi!$B$11,"")) | U22: =IF(D22="","",IF(J22<Asumsi!$B$20,"LOW DATA",IF(AND(B22="PROSP",ISNUMBER(M22),M22>=Asumsi!$B$21),"FATIGUE",IF(AND(ISNUMBER(N22),N22>=Asumsi!$B$22,ISNUMBER(Q22),Q22<Asumsi!$B$24),"FIX LANDING",IF(T22>=Asumsi!$B$16,"SCALE",IF(T22>=Asumsi!$B$26,"HOLD",IF(T22>=Asumsi!$B$27,"FIX","CUT")))))))
L23: =IF(D23="","",IFERROR(D23/E23*1000,"")) | M23: =IF(D23="","",IFERROR(E23/F23,"")) | N23: =IF(D23="","",IF(G23="","",IFERROR(G23/E23,""))) | O23: =IF(D23="","",IFERROR(H23/E23,"")) | P23: =IF(D23="","",IFERROR(D23/H23,"")) | Q23: =IF(D23="","",IFERROR(J23/H23,"")) | R23: =IF(D23="","",IFERROR(D23/J23,"")) | S23: =IF(D23="","",IFERROR(K23/D23,"")) | T23: =IF(D23="","",IFERROR(S23*Asumsi!$B$11,"")) | U23: =IF(D23="","",IF(J23<Asumsi!$B$20,"LOW DATA",IF(AND(B23="PROSP",ISNUMBER(M23),M23>=Asumsi!$B$21),"FATIGUE",IF(AND(ISNUMBER(N23),N23>=Asumsi!$B$22,ISNUMBER(Q23),Q23<Asumsi!$B$24),"FIX LANDING",IF(T23>=Asumsi!$B$16,"SCALE",IF(T23>=Asumsi!$B$26,"HOLD",IF(T23>=Asumsi!$B$27,"FIX","CUT")))))))
L24: =IF(D24="","",IFERROR(D24/E24*1000,"")) | M24: =IF(D24="","",IFERROR(E24/F24,"")) | N24: =IF(D24="","",IF(G24="","",IFERROR(G24/E24,""))) | O24: =IF(D24="","",IFERROR(H24/E24,"")) | P24: =IF(D24="","",IFERROR(D24/H24,"")) | Q24: =IF(D24="","",IFERROR(J24/H24,"")) | R24: =IF(D24="","",IFERROR(D24/J24,"")) | S24: =IF(D24="","",IFERROR(K24/D24,"")) | T24: =IF(D24="","",IFERROR(S24*Asumsi!$B$11,"")) | U24: =IF(D24="","",IF(J24<Asumsi!$B$20,"LOW DATA",IF(AND(B24="PROSP",ISNUMBER(M24),M24>=Asumsi!$B$21),"FATIGUE",IF(AND(ISNUMBER(N24),N24>=Asumsi!$B$22,ISNUMBER(Q24),Q24<Asumsi!$B$24),"FIX LANDING",IF(T24>=Asumsi!$B$16,"SCALE",IF(T24>=Asumsi!$B$26,"HOLD",IF(T24>=Asumsi!$B$27,"FIX","CUT")))))))
L25: =IF(D25="","",IFERROR(D25/E25*1000,"")) | M25: =IF(D25="","",IFERROR(E25/F25,"")) | N25: =IF(D25="","",IF(G25="","",IFERROR(G25/E25,""))) | O25: =IF(D25="","",IFERROR(H25/E25,"")) | P25: =IF(D25="","",IFERROR(D25/H25,"")) | Q25: =IF(D25="","",IFERROR(J25/H25,"")) | R25: =IF(D25="","",IFERROR(D25/J25,"")) | S25: =IF(D25="","",IFERROR(K25/D25,"")) | T25: =IF(D25="","",IFERROR(S25*Asumsi!$B$11,"")) | U25: =IF(D25="","",IF(J25<Asumsi!$B$20,"LOW DATA",IF(AND(B25="PROSP",ISNUMBER(M25),M25>=Asumsi!$B$21),"FATIGUE",IF(AND(ISNUMBER(N25),N25>=Asumsi!$B$22,ISNUMBER(Q25),Q25<Asumsi!$B$24),"FIX LANDING",IF(T25>=Asumsi!$B$16,"SCALE",IF(T25>=Asumsi!$B$26,"HOLD",IF(T25>=Asumsi!$B$27,"FIX","CUT")))))))
... L36: =IF(D36="","",IFERROR(D36/E36*1000,"")) | M36: =IF(D36="","",IFERROR(E36/F36,"")) | N36: =IF(D36="","",IF(G36="","",IFERROR(G36/E36,""))) | O36: =IF(D36="","",IFERROR(H36/E36,"")) | P36: =IF(D36="","",IFERROR(D36/H36,"")) | Q36: =IF(D36="","",IFERROR(J36/H36,"")) | R36: =IF(D36="","",IFERROR(D36/J36,"")) | S36: =IF(D36="","",IFERROR(K36/D36,"")) | T36: =IF(D36="","",IFERROR(S36*Asumsi!$B$11,"")) | U36: =IF(D36="","",IF(J36<Asumsi!$B$20,"LOW DATA",IF(AND(B36="PROSP",ISNUMBER(M36),M36>=Asumsi!$B$21),"FATIGUE",IF(AND(ISNUMBER(N36),N36>=Asumsi!$B$22,ISNUMBER(Q36),Q36<Asumsi!$B$24),"FIX LANDING",IF(T36>=Asumsi!$B$16,"SCALE",IF(T36>=Asumsi!$B$26,"HOLD",IF(T36>=Asumsi!$B$27,"FIX","CUT")))))))
A38: Cara baca: FATIGUE = frekuensi prospecting >= batas. FIX LANDING = hook bagus tapi klik jarang jadi beli. Ambang ada di sheet Asumsi.

Sheet TikTok Ads
A1: TikTok Ads: data per kreatif
A2: September 2026, data FIKTIF. Isi CTR minggu lalu untuk deteksi fatigue.
A5: TOTAL / RASIO | D5: =SUM(D7:D36) -> 28600000 | E5: =SUM(E7:E36) -> 3875000 | H5: =SUM(H7:H36) -> 26985 | I5: =SUM(I7:I36) -> 576 | J5: =SUM(J7:J36) -> 86400000 | L5: =IFERROR(D5/E5*1000,"") -> 7380.6452 | O5: =IFERROR(H5/E5,"") -> 0.006963871 | P5: =IFERROR(I5/H5,"") -> 0.021345192 | Q5: =IFERROR(D5/I5,"") -> 49652.778 | R5: =IFERROR(J5/D5,"") -> 3.020979 | S5: =IFERROR(R5*Asumsi!$B$11,"") -> 1.4198601
A6: Kreatif | B6: Tipe | C6: Campaign (TEST/SCALE/RET) | D6: Biaya (Rp) | E6: Impresi | F6: Tayang 2 detik | G6: Tayang 6 detik | H6: Klik | I6: Pembelian | J6: Omzet (Rp) | K6: CTR minggu lalu | L6: CPM (Rp) | M6: Hook rate (2s/impresi) | N6: Hold rate (6s/2s) | O6: CTR | P6: CVR | Q6: CPA (Rp) | R6: ROAS | S6: POAS | T6: Verdict
A7: Skit Pain Point v1 | B7: Spark Ads | C7: SCALE | D7: 8000000 | E7: 900000 | F7: 270000 | G7: 126000 | H7: 9000 | I7: 210 | J7: 31500000 | K7: 0.0095 | L7: =IF(D7="","",IFERROR(D7/E7*1000,"")) -> 8888.8889 | M7: =IF(D7="","",IF(F7="","",IFERROR(F7/E7,""))) -> 0.3 | N7: =IF(D7="","",IF(G7="","",IFERROR(G7/F7,""))) -> 0.46666667 | O7: =IF(D7="","",IFERROR(H7/E7,"")) -> 0.01 | P7: =IF(D7="","",IFERROR(I7/H7,"")) -> 0.023333333 | Q7: =IF(D7="","",IFERROR(D7/I7,"")) -> 38095.238 | R7: =IF(D7="","",IFERROR(J7/D7,"")) -> 3.9375 | S7: =IF(D7="","",IFERROR(R7*Asumsi!$B$11,"")) -> 1.850625 | T7: =IF(D7="","",IF(I7<Asumsi!$B$20,"LOW DATA",IF(AND(ISNUMBER(K7),ISNUMBER(O7),N(K7)>0,O7/N(K7)<Asumsi!$B$25),"FATIGUE",IF(AND(ISNUMBER(M7),M7>=Asumsi!$B$22,ISNUMBER(O7),O7<Asumsi!$B$23),"FIX CTA/BODY",IF(AND(ISNUMBER(M7),M7<Asumsi!$B$22,S7<Asumsi!$B$16),"FIX HOOK",IF(S7>=Asumsi!$B$16,"SCALE",IF(S7>=Asumsi!$B$26,"HOLD",IF(S7>=Asumsi!$B$27,"FIX","CUT")))))))) -> SCALE
A8: Creator Review (Spark) | B8: Spark Ads | C8: SCALE | D8: 6000000 | E8: 700000 | F8: 210000 | G8: 105000 | H8: 6300 | I8: 120 | J8: 18000000 | K8: 0.01 | L8: =IF(D8="","",IFERROR(D8/E8*1000,"")) -> 8571.4286 | M8: =IF(D8="","",IF(F8="","",IFERROR(F8/E8,""))) -> 0.3 | N8: =IF(D8="","",IF(G8="","",IFERROR(G8/F8,""))) -> 0.5 | O8: =IF(D8="","",IFERROR(H8/E8,"")) -> 0.009 | P8: =IF(D8="","",IFERROR(I8/H8,"")) -> 0.019047619 | Q8: =IF(D8="","",IFERROR(D8/I8,"")) -> 50000 | R8: =IF(D8="","",IFERROR(J8/D8,"")) -> 3 | S8: =IF(D8="","",IFERROR(R8*Asumsi!$B$11,"")) -> 1.41 | T8: =IF(D8="","",IF(I8<Asumsi!$B$20,"LOW DATA",IF(AND(ISNUMBER(K8),ISNUMBER(O8),N(K8)>0,O8/N(K8)<Asumsi!$B$25),"FATIGUE",IF(AND(ISNUMBER(M8),M8>=Asumsi!$B$22,ISNUMBER(O8),O8<Asumsi!$B$23),"FIX CTA/BODY",IF(AND(ISNUMBER(M8),M8<Asumsi!$B$22,S8<Asumsi!$B$16),"FIX HOOK",IF(S8>=Asumsi!$B$16,"SCALE",IF(S8>=Asumsi!$B$26,"HOLD",IF(S8>=Asumsi!$B$27,"FIX","CUT")))))))) -> SCALE
A9: Demo Produk ASMR | B9: Non-Spark | C9: TEST | D9: 4000000 | E9: 550000 | F9: 88000 | G9: 44000 | H9: 2750 | I9: 65 | J9: 9750000 | K9: 0.005 | L9: =IF(D9="","",IFERROR(D9/E9*1000,"")) -> 7272.7273 | M9: =IF(D9="","",IF(F9="","",IFERROR(F9/E9,""))) -> 0.16 | N9: =IF(D9="","",IF(G9="","",IFERROR(G9/F9,""))) -> 0.5 | O9: =IF(D9="","",IFERROR(H9/E9,"")) -> 0.005 | P9: =IF(D9="","",IFERROR(I9/H9,"")) -> 0.023636364 | Q9: =IF(D9="","",IFERROR(D9/I9,"")) -> 61538.462 | R9: =IF(D9="","",IFERROR(J9/D9,"")) -> 2.4375 | S9: =IF(D9="","",IFERROR(R9*Asumsi!$B$11,"")) -> 1.145625 | T9: =IF(D9="","",IF(I9<Asumsi!$B$20,"LOW DATA",IF(AND(ISNUMBER(K9),ISNUMBER(O9),N(K9)>0,O9/N(K9)<Asumsi!$B$25),"FATIGUE",IF(AND(ISNUMBER(M9),M9>=Asumsi!$B$22,ISNUMBER(O9),O9<Asumsi!$B$23),"FIX CTA/BODY",IF(AND(ISNUMBER(M9),M9<Asumsi!$B$22,S9<Asumsi!$B$16),"FIX HOOK",IF(S9>=Asumsi!$B$16,"SCALE",IF(S9>=Asumsi!$B$26,"HOLD",IF(S9>=Asumsi!$B$27,"FIX","CUT")))))))) -> FIX HOOK
A10: Trend Sound Dance | B10: Non-Spark | C10: TEST | D10: 3000000 | E10: 800000 | F10: 320000 | G10: 96000 | H10: 1600 | I10: 18 | J10: 2700000 | K10: 0.002 | L10: =IF(D10="","",IFERROR(D10/E10*1000,"")) -> 3750 | M10: =IF(D10="","",IF(F10="","",IFERROR(F10/E10,""))) -> 0.4 | N10: =IF(D10="","",IF(G10="","",IFERROR(G10/F10,""))) -> 0.3 | O10: =IF(D10="","",IFERROR(H10/E10,"")) -> 0.002 | P10: =IF(D10="","",IFERROR(I10/H10,"")) -> 0.01125 | Q10: =IF(D10="","",IFERROR(D10/I10,"")) -> 166666.67 | R10: =IF(D10="","",IFERROR(J10/D10,"")) -> 0.9 | S10: =IF(D10="","",IFERROR(R10*Asumsi!$B$11,"")) -> 0.423 | T10: =IF(D10="","",IF(I10<Asumsi!$B$20,"LOW DATA",IF(AND(ISNUMBER(K10),ISNUMBER(O10),N(K10)>0,O10/N(K10)<Asumsi!$B$25),"FATIGUE",IF(AND(ISNUMBER(M10),M10>=Asumsi!$B$22,ISNUMBER(O10),O10<Asumsi!$B$23),"FIX CTA/BODY",IF(AND(ISNUMBER(M10),M10<Asumsi!$B$22,S10<Asumsi!$B$16),"FIX HOOK",IF(S10>=Asumsi!$B$16,"SCALE",IF(S10>=Asumsi!$B$26,"HOLD",IF(S10>=Asumsi!$B$27,"FIX","CUT")))))))) -> FIX CTA/BODY
A11: Promo Flash Sale v3 (hari ke-18) | B11: Non-Spark | C11: SCALE | D11: 5000000 | E11: 650000 | F11: 156000 | G11: 70200 | H11: 3575 | I11: 70 | J11: 10500000 | K11: 0.011 | L11: =IF(D11="","",IFERROR(D11/E11*1000,"")) -> 7692.3077 | M11: =IF(D11="","",IF(F11="","",IFERROR(F11/E11,""))) -> 0.24 | N11: =IF(D11="","",IF(G11="","",IFERROR(G11/F11,""))) -> 0.45 | O11: =IF(D11="","",IFERROR(H11/E11,"")) -> 0.0055 | P11: =IF(D11="","",IFERROR(I11/H11,"")) -> 0.01958042 | Q11: =IF(D11="","",IFERROR(D11/I11,"")) -> 71428.571 | R11: =IF(D11="","",IFERROR(J11/D11,"")) -> 2.1 | S11: =IF(D11="","",IFERROR(R11*Asumsi!$B$11,"")) -> 0.987 | T11: =IF(D11="","",IF(I11<Asumsi!$B$20,"LOW DATA",IF(AND(ISNUMBER(K11),ISNUMBER(O11),N(K11)>0,O11/N(K11)<Asumsi!$B$25),"FATIGUE",IF(AND(ISNUMBER(M11),M11>=Asumsi!$B$22,ISNUMBER(O11),O11<Asumsi!$B$23),"FIX CTA/BODY",IF(AND(ISNUMBER(M11),M11<Asumsi!$B$22,S11<Asumsi!$B$16),"FIX HOOK",IF(S11>=Asumsi!$B$16,"SCALE",IF(S11>=Asumsi!$B$26,"HOLD",IF(S11>=Asumsi!$B$27,"FIX","CUT")))))))) -> FATIGUE
A12: Retargeting Penonton Video | B12: Non-Spark | C12: RET | D12: 2000000 | E12: 180000 | F12: 50400 | G12: 27000 | H12: 3000 | I12: 90 | J12: 13500000 | K12: 0.016 | L12: =IF(D12="","",IFERROR(D12/E12*1000,"")) -> 11111.111 | M12: =IF(D12="","",IF(F12="","",IFERROR(F12/E12,""))) -> 0.28 | N12: =IF(D12="","",IF(G12="","",IFERROR(G12/F12,""))) -> 0.53571429 | O12: =IF(D12="","",IFERROR(H12/E12,"")) -> 0.016666667 | P12: =IF(D12="","",IFERROR(I12/H12,"")) -> 0.03 | Q12: =IF(D12="","",IFERROR(D12/I12,"")) -> 22222.222 | R12: =IF(D12="","",IFERROR(J12/D12,"")) -> 6.75 | S12: =IF(D12="","",IFERROR(R12*Asumsi!$B$11,"")) -> 3.1725 | T12: =IF(D12="","",IF(I12<Asumsi!$B$20,"LOW DATA",IF(AND(ISNUMBER(K12),ISNUMBER(O12),N(K12)>0,O12/N(K12)<Asumsi!$B$25),"FATIGUE",IF(AND(ISNUMBER(M12),M12>=Asumsi!$B$22,ISNUMBER(O12),O12<Asumsi!$B$23),"FIX CTA/BODY",IF(AND(ISNUMBER(M12),M12<Asumsi!$B$22,S12<Asumsi!$B$16),"FIX HOOK",IF(S12>=Asumsi!$B$16,"SCALE",IF(S12>=Asumsi!$B$26,"HOLD",IF(S12>=Asumsi!$B$27,"FIX","CUT")))))))) -> SCALE
A13: Unboxing Hemat v1 (tes baru) | B13: Non-Spark | C13: TEST | D13: 600000 | E13: 95000 | F13: 26600 | G13: 11000 | H13: 760 | I13: 3 | J13: 450000 | L13: =IF(D13="","",IFERROR(D13/E13*1000,"")) -> 6315.7895 | M13: =IF(D13="","",IF(F13="","",IFERROR(F13/E13,""))) -> 0.28 | N13: =IF(D13="","",IF(G13="","",IFERROR(G13/F13,""))) -> 0.41353383 | O13: =IF(D13="","",IFERROR(H13/E13,"")) -> 0.008 | P13: =IF(D13="","",IFERROR(I13/H13,"")) -> 0.0039473684 | Q13: =IF(D13="","",IFERROR(D13/I13,"")) -> 200000 | R13: =IF(D13="","",IFERROR(J13/D13,"")) -> 0.75 | S13: =IF(D13="","",IFERROR(R13*Asumsi!$B$11,"")) -> 0.3525 | T13: =IF(D13="","",IF(I13<Asumsi!$B$20,"LOW DATA",IF(AND(ISNUMBER(K13),ISNUMBER(O13),N(K13)>0,O13/N(K13)<Asumsi!$B$25),"FATIGUE",IF(AND(ISNUMBER(M13),M13>=Asumsi!$B$22,ISNUMBER(O13),O13<Asumsi!$B$23),"FIX CTA/BODY",IF(AND(ISNUMBER(M13),M13<Asumsi!$B$22,S13<Asumsi!$B$16),"FIX HOOK",IF(S13>=Asumsi!$B$16,"SCALE",IF(S13>=Asumsi!$B$26,"HOLD",IF(S13>=Asumsi!$B$27,"FIX","CUT")))))))) -> LOW DATA
L14: =IF(D14="","",IFERROR(D14/E14*1000,"")) | M14: =IF(D14="","",IF(F14="","",IFERROR(F14/E14,""))) | N14: =IF(D14="","",IF(G14="","",IFERROR(G14/F14,""))) | O14: =IF(D14="","",IFERROR(H14/E14,"")) | P14: =IF(D14="","",IFERROR(I14/H14,"")) | Q14: =IF(D14="","",IFERROR(D14/I14,"")) | R14: =IF(D14="","",IFERROR(J14/D14,"")) | S14: =IF(D14="","",IFERROR(R14*Asumsi!$B$11,"")) | T14: =IF(D14="","",IF(I14<Asumsi!$B$20,"LOW DATA",IF(AND(ISNUMBER(K14),ISNUMBER(O14),N(K14)>0,O14/N(K14)<Asumsi!$B$25),"FATIGUE",IF(AND(ISNUMBER(M14),M14>=Asumsi!$B$22,ISNUMBER(O14),O14<Asumsi!$B$23),"FIX CTA/BODY",IF(AND(ISNUMBER(M14),M14<Asumsi!$B$22,S14<Asumsi!$B$16),"FIX HOOK",IF(S14>=Asumsi!$B$16,"SCALE",IF(S14>=Asumsi!$B$26,"HOLD",IF(S14>=Asumsi!$B$27,"FIX","CUT"))))))))
L15: =IF(D15="","",IFERROR(D15/E15*1000,"")) | M15: =IF(D15="","",IF(F15="","",IFERROR(F15/E15,""))) | N15: =IF(D15="","",IF(G15="","",IFERROR(G15/F15,""))) | O15: =IF(D15="","",IFERROR(H15/E15,"")) | P15: =IF(D15="","",IFERROR(I15/H15,"")) | Q15: =IF(D15="","",IFERROR(D15/I15,"")) | R15: =IF(D15="","",IFERROR(J15/D15,"")) | S15: =IF(D15="","",IFERROR(R15*Asumsi!$B$11,"")) | T15: =IF(D15="","",IF(I15<Asumsi!$B$20,"LOW DATA",IF(AND(ISNUMBER(K15),ISNUMBER(O15),N(K15)>0,O15/N(K15)<Asumsi!$B$25),"FATIGUE",IF(AND(ISNUMBER(M15),M15>=Asumsi!$B$22,ISNUMBER(O15),O15<Asumsi!$B$23),"FIX CTA/BODY",IF(AND(ISNUMBER(M15),M15<Asumsi!$B$22,S15<Asumsi!$B$16),"FIX HOOK",IF(S15>=Asumsi!$B$16,"SCALE",IF(S15>=Asumsi!$B$26,"HOLD",IF(S15>=Asumsi!$B$27,"FIX","CUT"))))))))
L16: =IF(D16="","",IFERROR(D16/E16*1000,"")) | M16: =IF(D16="","",IF(F16="","",IFERROR(F16/E16,""))) | N16: =IF(D16="","",IF(G16="","",IFERROR(G16/F16,""))) | O16: =IF(D16="","",IFERROR(H16/E16,"")) | P16: =IF(D16="","",IFERROR(I16/H16,"")) | Q16: =IF(D16="","",IFERROR(D16/I16,"")) | R16: =IF(D16="","",IFERROR(J16/D16,"")) | S16: =IF(D16="","",IFERROR(R16*Asumsi!$B$11,"")) | T16: =IF(D16="","",IF(I16<Asumsi!$B$20,"LOW DATA",IF(AND(ISNUMBER(K16),ISNUMBER(O16),N(K16)>0,O16/N(K16)<Asumsi!$B$25),"FATIGUE",IF(AND(ISNUMBER(M16),M16>=Asumsi!$B$22,ISNUMBER(O16),O16<Asumsi!$B$23),"FIX CTA/BODY",IF(AND(ISNUMBER(M16),M16<Asumsi!$B$22,S16<Asumsi!$B$16),"FIX HOOK",IF(S16>=Asumsi!$B$16,"SCALE",IF(S16>=Asumsi!$B$26,"HOLD",IF(S16>=Asumsi!$B$27,"FIX","CUT"))))))))
L17: =IF(D17="","",IFERROR(D17/E17*1000,"")) | M17: =IF(D17="","",IF(F17="","",IFERROR(F17/E17,""))) | N17: =IF(D17="","",IF(G17="","",IFERROR(G17/F17,""))) | O17: =IF(D17="","",IFERROR(H17/E17,"")) | P17: =IF(D17="","",IFERROR(I17/H17,"")) | Q17: =IF(D17="","",IFERROR(D17/I17,"")) | R17: =IF(D17="","",IFERROR(J17/D17,"")) | S17: =IF(D17="","",IFERROR(R17*Asumsi!$B$11,"")) | T17: =IF(D17="","",IF(I17<Asumsi!$B$20,"LOW DATA",IF(AND(ISNUMBER(K17),ISNUMBER(O17),N(K17)>0,O17/N(K17)<Asumsi!$B$25),"FATIGUE",IF(AND(ISNUMBER(M17),M17>=Asumsi!$B$22,ISNUMBER(O17),O17<Asumsi!$B$23),"FIX CTA/BODY",IF(AND(ISNUMBER(M17),M17<Asumsi!$B$22,S17<Asumsi!$B$16),"FIX HOOK",IF(S17>=Asumsi!$B$16,"SCALE",IF(S17>=Asumsi!$B$26,"HOLD",IF(S17>=Asumsi!$B$27,"FIX","CUT"))))))))
L18: =IF(D18="","",IFERROR(D18/E18*1000,"")) | M18: =IF(D18="","",IF(F18="","",IFERROR(F18/E18,""))) | N18: =IF(D18="","",IF(G18="","",IFERROR(G18/F18,""))) | O18: =IF(D18="","",IFERROR(H18/E18,"")) | P18: =IF(D18="","",IFERROR(I18/H18,"")) | Q18: =IF(D18="","",IFERROR(D18/I18,"")) | R18: =IF(D18="","",IFERROR(J18/D18,"")) | S18: =IF(D18="","",IFERROR(R18*Asumsi!$B$11,"")) | T18: =IF(D18="","",IF(I18<Asumsi!$B$20,"LOW DATA",IF(AND(ISNUMBER(K18),ISNUMBER(O18),N(K18)>0,O18/N(K18)<Asumsi!$B$25),"FATIGUE",IF(AND(ISNUMBER(M18),M18>=Asumsi!$B$22,ISNUMBER(O18),O18<Asumsi!$B$23),"FIX CTA/BODY",IF(AND(ISNUMBER(M18),M18<Asumsi!$B$22,S18<Asumsi!$B$16),"FIX HOOK",IF(S18>=Asumsi!$B$16,"SCALE",IF(S18>=Asumsi!$B$26,"HOLD",IF(S18>=Asumsi!$B$27,"FIX","CUT"))))))))
L19: =IF(D19="","",IFERROR(D19/E19*1000,"")) | M19: =IF(D19="","",IF(F19="","",IFERROR(F19/E19,""))) | N19: =IF(D19="","",IF(G19="","",IFERROR(G19/F19,""))) | O19: =IF(D19="","",IFERROR(H19/E19,"")) | P19: =IF(D19="","",IFERROR(I19/H19,"")) | Q19: =IF(D19="","",IFERROR(D19/I19,"")) | R19: =IF(D19="","",IFERROR(J19/D19,"")) | S19: =IF(D19="","",IFERROR(R19*Asumsi!$B$11,"")) | T19: =IF(D19="","",IF(I19<Asumsi!$B$20,"LOW DATA",IF(AND(ISNUMBER(K19),ISNUMBER(O19),N(K19)>0,O19/N(K19)<Asumsi!$B$25),"FATIGUE",IF(AND(ISNUMBER(M19),M19>=Asumsi!$B$22,ISNUMBER(O19),O19<Asumsi!$B$23),"FIX CTA/BODY",IF(AND(ISNUMBER(M19),M19<Asumsi!$B$22,S19<Asumsi!$B$16),"FIX HOOK",IF(S19>=Asumsi!$B$16,"SCALE",IF(S19>=Asumsi!$B$26,"HOLD",IF(S19>=Asumsi!$B$27,"FIX","CUT"))))))))
L20: =IF(D20="","",IFERROR(D20/E20*1000,"")) | M20: =IF(D20="","",IF(F20="","",IFERROR(F20/E20,""))) | N20: =IF(D20="","",IF(G20="","",IFERROR(G20/F20,""))) | O20: =IF(D20="","",IFERROR(H20/E20,"")) | P20: =IF(D20="","",IFERROR(I20/H20,"")) | Q20: =IF(D20="","",IFERROR(D20/I20,"")) | R20: =IF(D20="","",IFERROR(J20/D20,"")) | S20: =IF(D20="","",IFERROR(R20*Asumsi!$B$11,"")) | T20: =IF(D20="","",IF(I20<Asumsi!$B$20,"LOW DATA",IF(AND(ISNUMBER(K20),ISNUMBER(O20),N(K20)>0,O20/N(K20)<Asumsi!$B$25),"FATIGUE",IF(AND(ISNUMBER(M20),M20>=Asumsi!$B$22,ISNUMBER(O20),O20<Asumsi!$B$23),"FIX CTA/BODY",IF(AND(ISNUMBER(M20),M20<Asumsi!$B$22,S20<Asumsi!$B$16),"FIX HOOK",IF(S20>=Asumsi!$B$16,"SCALE",IF(S20>=Asumsi!$B$26,"HOLD",IF(S20>=Asumsi!$B$27,"FIX","CUT"))))))))
L21: =IF(D21="","",IFERROR(D21/E21*1000,"")) | M21: =IF(D21="","",IF(F21="","",IFERROR(F21/E21,""))) | N21: =IF(D21="","",IF(G21="","",IFERROR(G21/F21,""))) | O21: =IF(D21="","",IFERROR(H21/E21,"")) | P21: =IF(D21="","",IFERROR(I21/H21,"")) | Q21: =IF(D21="","",IFERROR(D21/I21,"")) | R21: =IF(D21="","",IFERROR(J21/D21,"")) | S21: =IF(D21="","",IFERROR(R21*Asumsi!$B$11,"")) | T21: =IF(D21="","",IF(I21<Asumsi!$B$20,"LOW DATA",IF(AND(ISNUMBER(K21),ISNUMBER(O21),N(K21)>0,O21/N(K21)<Asumsi!$B$25),"FATIGUE",IF(AND(ISNUMBER(M21),M21>=Asumsi!$B$22,ISNUMBER(O21),O21<Asumsi!$B$23),"FIX CTA/BODY",IF(AND(ISNUMBER(M21),M21<Asumsi!$B$22,S21<Asumsi!$B$16),"FIX HOOK",IF(S21>=Asumsi!$B$16,"SCALE",IF(S21>=Asumsi!$B$26,"HOLD",IF(S21>=Asumsi!$B$27,"FIX","CUT"))))))))
L22: =IF(D22="","",IFERROR(D22/E22*1000,"")) | M22: =IF(D22="","",IF(F22="","",IFERROR(F22/E22,""))) | N22: =IF(D22="","",IF(G22="","",IFERROR(G22/F22,""))) | O22: =IF(D22="","",IFERROR(H22/E22,"")) | P22: =IF(D22="","",IFERROR(I22/H22,"")) | Q22: =IF(D22="","",IFERROR(D22/I22,"")) | R22: =IF(D22="","",IFERROR(J22/D22,"")) | S22: =IF(D22="","",IFERROR(R22*Asumsi!$B$11,"")) | T22: =IF(D22="","",IF(I22<Asumsi!$B$20,"LOW DATA",IF(AND(ISNUMBER(K22),ISNUMBER(O22),N(K22)>0,O22/N(K22)<Asumsi!$B$25),"FATIGUE",IF(AND(ISNUMBER(M22),M22>=Asumsi!$B$22,ISNUMBER(O22),O22<Asumsi!$B$23),"FIX CTA/BODY",IF(AND(ISNUMBER(M22),M22<Asumsi!$B$22,S22<Asumsi!$B$16),"FIX HOOK",IF(S22>=Asumsi!$B$16,"SCALE",IF(S22>=Asumsi!$B$26,"HOLD",IF(S22>=Asumsi!$B$27,"FIX","CUT"))))))))
L23: =IF(D23="","",IFERROR(D23/E23*1000,"")) | M23: =IF(D23="","",IF(F23="","",IFERROR(F23/E23,""))) | N23: =IF(D23="","",IF(G23="","",IFERROR(G23/F23,""))) | O23: =IF(D23="","",IFERROR(H23/E23,"")) | P23: =IF(D23="","",IFERROR(I23/H23,"")) | Q23: =IF(D23="","",IFERROR(D23/I23,"")) | R23: =IF(D23="","",IFERROR(J23/D23,"")) | S23: =IF(D23="","",IFERROR(R23*Asumsi!$B$11,"")) | T23: =IF(D23="","",IF(I23<Asumsi!$B$20,"LOW DATA",IF(AND(ISNUMBER(K23),ISNUMBER(O23),N(K23)>0,O23/N(K23)<Asumsi!$B$25),"FATIGUE",IF(AND(ISNUMBER(M23),M23>=Asumsi!$B$22,ISNUMBER(O23),O23<Asumsi!$B$23),"FIX CTA/BODY",IF(AND(ISNUMBER(M23),M23<Asumsi!$B$22,S23<Asumsi!$B$16),"FIX HOOK",IF(S23>=Asumsi!$B$16,"SCALE",IF(S23>=Asumsi!$B$26,"HOLD",IF(S23>=Asumsi!$B$27,"FIX","CUT"))))))))
L24: =IF(D24="","",IFERROR(D24/E24*1000,"")) | M24: =IF(D24="","",IF(F24="","",IFERROR(F24/E24,""))) | N24: =IF(D24="","",IF(G24="","",IFERROR(G24/F24,""))) | O24: =IF(D24="","",IFERROR(H24/E24,"")) | P24: =IF(D24="","",IFERROR(I24/H24,"")) | Q24: =IF(D24="","",IFERROR(D24/I24,"")) | R24: =IF(D24="","",IFERROR(J24/D24,"")) | S24: =IF(D24="","",IFERROR(R24*Asumsi!$B$11,"")) | T24: =IF(D24="","",IF(I24<Asumsi!$B$20,"LOW DATA",IF(AND(ISNUMBER(K24),ISNUMBER(O24),N(K24)>0,O24/N(K24)<Asumsi!$B$25),"FATIGUE",IF(AND(ISNUMBER(M24),M24>=Asumsi!$B$22,ISNUMBER(O24),O24<Asumsi!$B$23),"FIX CTA/BODY",IF(AND(ISNUMBER(M24),M24<Asumsi!$B$22,S24<Asumsi!$B$16),"FIX HOOK",IF(S24>=Asumsi!$B$16,"SCALE",IF(S24>=Asumsi!$B$26,"HOLD",IF(S24>=Asumsi!$B$27,"FIX","CUT"))))))))
L25: =IF(D25="","",IFERROR(D25/E25*1000,"")) | M25: =IF(D25="","",IF(F25="","",IFERROR(F25/E25,""))) | N25: =IF(D25="","",IF(G25="","",IFERROR(G25/F25,""))) | O25: =IF(D25="","",IFERROR(H25/E25,"")) | P25: =IF(D25="","",IFERROR(I25/H25,"")) | Q25: =IF(D25="","",IFERROR(D25/I25,"")) | R25: =IF(D25="","",IFERROR(J25/D25,"")) | S25: =IF(D25="","",IFERROR(R25*Asumsi!$B$11,"")) | T25: =IF(D25="","",IF(I25<Asumsi!$B$20,"LOW DATA",IF(AND(ISNUMBER(K25),ISNUMBER(O25),N(K25)>0,O25/N(K25)<Asumsi!$B$25),"FATIGUE",IF(AND(ISNUMBER(M25),M25>=Asumsi!$B$22,ISNUMBER(O25),O25<Asumsi!$B$23),"FIX CTA/BODY",IF(AND(ISNUMBER(M25),M25<Asumsi!$B$22,S25<Asumsi!$B$16),"FIX HOOK",IF(S25>=Asumsi!$B$16,"SCALE",IF(S25>=Asumsi!$B$26,"HOLD",IF(S25>=Asumsi!$B$27,"FIX","CUT"))))))))
... L36: =IF(D36="","",IFERROR(D36/E36*1000,"")) | M36: =IF(D36="","",IF(F36="","",IFERROR(F36/E36,""))) | N36: =IF(D36="","",IF(G36="","",IFERROR(G36/F36,""))) | O36: =IF(D36="","",IFERROR(H36/E36,"")) | P36: =IF(D36="","",IFERROR(I36/H36,"")) | Q36: =IF(D36="","",IFERROR(D36/I36,"")) | R36: =IF(D36="","",IFERROR(J36/D36,"")) | S36: =IF(D36="","",IFERROR(R36*Asumsi!$B$11,"")) | T36: =IF(D36="","",IF(I36<Asumsi!$B$20,"LOW DATA",IF(AND(ISNUMBER(K36),ISNUMBER(O36),N(K36)>0,O36/N(K36)<Asumsi!$B$25),"FATIGUE",IF(AND(ISNUMBER(M36),M36>=Asumsi!$B$22,ISNUMBER(O36),O36<Asumsi!$B$23),"FIX CTA/BODY",IF(AND(ISNUMBER(M36),M36<Asumsi!$B$22,S36<Asumsi!$B$16),"FIX HOOK",IF(S36>=Asumsi!$B$16,"SCALE",IF(S36>=Asumsi!$B$26,"HOLD",IF(S36>=Asumsi!$B$27,"FIX","CUT"))))))))
A38: Cara baca: FATIGUE = CTR sekarang jatuh di bawah rasio batas dari CTR minggu lalu. FIX CTA/BODY = hook kuat tapi klik sedikit. FIX HOOK = 2 detik pertama lemah.

Sheet LinkedIn Ads
A1: LinkedIn Ads: B2B seragam korporat
A2: September 2026, data FIKTIF. Hasil dilihat sampai SQL dan deal, bukan hanya lead. Won = deal yang sudah closing di periode ini (siklus B2B panjang).
A5: TOTAL / RASIO | D5: =SUM(D7:D36) -> 81000000 | E5: =SUM(E7:E36) -> 840000 | F5: =SUM(F7:F36) -> 6500 | G5: =SUM(G7:G36) -> 209 | H5: =SUM(H7:H36) -> 39 | I5: =SUM(I7:I36) -> 19 | J5: =SUM(J7:J36) -> 6 | K5: =SUM(K7:K36) -> 260000000 | L5: =IFERROR(F5/E5,"") -> 0.0077380952 | M5: =IFERROR(D5/F5,"") -> 12461.538 | N5: =IFERROR(D5/G5,"") -> 387559.81 | O5: =IFERROR(H5/G5,"") -> 0.18660287 | P5: =IFERROR(D5/H5,"") -> 2076923.1 | Q5: =IFERROR(D5/I5,"") -> 4263157.9 | R5: =IFERROR(K5/D5,"") -> 3.2098765 | S5: =IFERROR(K5*Asumsi!$B$31/D5,"") -> 0.96296296
A6: Campaign | B6: Audiens | C6: Format | D6: Biaya (Rp) | E6: Impresi | F6: Klik | G6: Lead | H6: SQL | I6: Peluang (Opp) | J6: Deal Won | K6: Omzet Won (Rp) | L6: CTR | M6: CPC (Rp) | N6: Biaya/Lead (Rp) | O6: Lead ke SQL | P6: Biaya/SQL (Rp) | Q6: Biaya/Opp (Rp) | R6: ROAS Won | S6: POAS Won | T6: Verdict
A7: Lead Gen Form: Panduan Pengadaan Seragam | B7: Manajer Pengadaan, 200-5000 karyawan | C7: Lead Gen Form | D7: 25000000 | E7: 210000 | F7: 1100 | G7: 96 | H7: 8 | I7: 4 | J7: 1 | K7: 45000000 | L7: =IF(D7="","",IFERROR(F7/E7,"")) -> 0.0052380952 | M7: =IF(D7="","",IFERROR(D7/F7,"")) -> 22727.273 | N7: =IF(D7="","",IFERROR(D7/G7,"")) -> 260416.67 | O7: =IF(D7="","",IFERROR(H7/G7,"")) -> 0.083333333 | P7: =IF(D7="","",IFERROR(D7/H7,"")) -> 3125000 | Q7: =IF(D7="","",IFERROR(D7/I7,"")) -> 6250000 | R7: =IF(D7="","",IFERROR(K7/D7,"")) -> 1.8 | S7: =IF(D7="","",IFERROR(K7*Asumsi!$B$31/D7,"")) -> 0.54 | T7: =IF(D7="","",IF(H7<Asumsi!$B$37,"LOW DATA",IF(P7<=Asumsi!$B$36,"SCALE",IF(P7<=1.5*Asumsi!$B$36,"HOLD","CUT")))) -> CUT
